Workbook

Sheet AllProteins
A1: GeneOrder | B1: GroupName | C1: GroupProteinFunction | D1: GeneAccession | E1: GeneLink | F1: GeneProteinFunction | G1: IsolateName | H1: IsolateAccession | I1: =INDEX(Genomes!$I:$I,(MATCH(AllProteins!H1,Genomes!$B:$B,0))) -> GenomeDisplayName | J1: =INDEX(Genomes!$A:$A,(MATCH(AllProteins!H1,Genomes!$B:$B,0))) -> GenomeOrder | K1: =INDEX(Genomes!$J:$J,(MATCH(AllProteins!H1,Genomes!$B:$B,0))) -> inNewPoxAlign
A2: =INDEX(CoreProteinGroups!A:A,MATCH(B2,CoreProteinGroups!B:B,0)) -> 1 | B2: A18 | C2: =VLOOKUP(B2,CoreProteinGroups!$B:$C,2,FALSE) -> DNA helicase | D2: ATI21220.1 | E2: =HYPERLINK(_xlfn.CONCAT("https://www.ncbi.nlm.nih.gov/protein/",D2),_xlfn.CONCAT("PROT:",D2)) -> PROT:ATI21220.1 | F2: DNA helicase transcript release factor | G2: Eastern grey kangaroopox virus | H2: MF467281.1 | I2: =INDEX(Genomes!$I:$I,(MATCH(AllProteins!H2,Genomes!$B:$B,0))) -> MF467281-Eastern_grey_kangaroopox_virus | J2: =INDEX(Genomes!$A:$A,(MATCH(AllProteins!H2,Genomes!$B:$B,0))) -> 18 | K2: =INDEX(Genomes!$J:$J,(MATCH(AllProteins!H2,Genomes!$B:$B,0))) -> Y
A3: =INDEX(CoreProteinGroups!A:A,MATCH(B3,CoreProteinGroups!B:B,0)) -> 1 | B3: A18 | C3: =VLOOKUP(B3,CoreProteinGroups!$B:$C,2,FALSE) -> DNA helicase | D3: AWU47153.1 | E3: =HYPERLINK(_xlfn.CONCAT("https://www.ncbi.nlm.nih.gov/protein/",D3),_xlfn.CONCAT("PROT:",D3)) -> PROT:AWU47153.1 | F3: DNA helicase | G3: Sea otter poxvirus | H3: MH427217.1 | I3: =INDEX(Genomes!$I:$I,(MATCH(AllProteins!H3,Genomes!$B:$B,0))) -> MH427217-sea_otter_poxvirus | J3: =INDEX(Genomes!$A:$A,(MATCH(AllProteins!H3,Genomes!$B:$B,0))) -> 47 | K3: =INDEX(Genomes!$J:$J,(MATCH(AllProteins!H3,Genomes!$B:$B,0))) -> Y
A4: =INDEX(CoreProteinGroups!A:A,MATCH(B4,CoreProteinGroups!B:B,0)) -> 1 | B4: A18 | C4: =VLOOKUP(B4,CoreProteinGroups!$B:$C,2,FALSE) -> DNA helicase | D4: APG58328.1 | E4: =HYPERLINK(_xlfn.CONCAT("https://www.ncbi.nlm.nih.gov/protein/",D4),_xlfn.CONCAT("PROT:",D4)) -> PROT:APG58328.1 | F4: transcript termination protein A18 | G4: BeAn 58058 virus | H4: KY094066.1 | I4: =INDEX(Genomes!$I:$I,(MATCH(AllProteins!H4,Genomes!$B:$B,0))) -> KY094066-BeAn_58058_virus | J4: =INDEX(Genomes!$A:$A,(MATCH(AllProteins!H4,Genomes!$B:$B,0))) -> 7 | K4: =INDEX(Genomes!$J:$J,(MATCH(AllProteins!H4,Genomes!$B:$B,0))) -> N
A5: =INDEX(CoreProteinGroups!A:A,MATCH(B5,CoreProteinGroups!B:B,0)) -> 1 | B5: A18 | C5: =VLOOKUP(B5,CoreProteinGroups!$B:$C,2,FALSE) -> DNA helicase | D5: ADT91137.1 | E5: =HYPERLINK(_xlfn.CONCAT("https://www.ncbi.nlm.nih.gov/protein/",D5),_xlfn.CONCAT("PROT:",D5)) -> PROT:ADT91137.1 | F5: DNA helicase-transcription elongation factor | G5: Cotia virus SPAn232 | H5: HQ647181.2 | I5: =INDEX(Genomes!$I:$I,(MATCH(AllProteins!H5,Genomes!$B:$B,0))) -> HQ647181-Cotia_virus | J5: =INDEX(Genomes!$A:$A,(MATCH(AllProteins!H5,Genomes!$B:$B,0))) -> 12 | K5: =INDEX(Genomes!$J:$J,(MATCH(AllProteins!H5,Genomes!$B:$B,0))) -> Y
A6: =INDEX(CoreProteinGroups!A:A,MATCH(B6,CoreProteinGroups!B:B,0)) -> 1 | B6: A18 | C6: =VLOOKUP(B6,CoreProteinGroups!$B:$C,2,FALSE) -> DNA helicase | D6: ANS71197.1 | E6: =HYPERLINK(_xlfn.CONCAT("https://www.ncbi.nlm.nih.gov/protein/",D6),_xlfn.CONCAT("PROT:",D6)) -> PROT:ANS71197.1 | F6: DNA helicase transcript release factor | G6: Pteropox virus | H6: KU980965.1 | I6: =INDEX(Genomes!$I:$I,(MATCH(AllProteins!H6,Genomes!$B:$B,0))) -> KU980965-pteropox_virus | J6: =INDEX(Genomes!$A:$A,(MATCH(AllProteins!H6,Genomes!$B:$B,0))) -> 40 | K6: =INDEX(Genomes!$J:$J,(MATCH(AllProteins!H6,Genomes!$B:$B,0))) -> Y
A7: =INDEX(CoreProteinGroups!A:A,MATCH(B7,CoreProteinGroups!B:B,0)) -> 1 | B7: A18 | C7: =VLOOKUP(B7,CoreProteinGroups!$B:$C,2,FALSE) -> DNA helicase | D7: AKR04244.1 | E7: =HYPERLINK(_xlfn.CONCAT("https://www.ncbi.nlm.nih.gov/protein/",D7),_xlfn.CONCAT("PROT:",D7)) -> PROT:AKR04244.1 | F7: DNA or RNA helicases of superfamily II | G7: Salmon gill poxvirus | H7: KT159937.1 | I7: =INDEX(Genomes!$I:$I,(MATCH(AllProteins!H7,Genomes!$B:$B,0))) -> KT159937-salmon_gill_poxvirus | J7: =INDEX(Genomes!$A:$A,(MATCH(AllProteins!H7,Genomes!$B:$B,0))) -> 46 | K7: =INDEX(Genomes!$J:$J,(MATCH(AllProteins!H7,Genomes!$B:$B,0))) -> Y
A8: =INDEX(CoreProteinGroups!A:A,MATCH(B8,CoreProteinGroups!B:B,0)) -> 1 | B8: A18 | C8: =VLOOKUP(B8,CoreProteinGroups!$B:$C,2,FALSE) -> DNA helicase | D8: CCD83290.1 | E8: =HYPERLINK(_xlfn.CONCAT("https://www.ncbi.nlm.nih.gov/protein/",D8),_xlfn.CONCAT("PROT:",D8)) -> PROT:CCD83290.1 | F8: transcript release/DNA helicase | G8: Squirrelpox virus | H8: HE601899.1 | I8: =INDEX(Genomes!$I:$I,(MATCH(AllProteins!H8,Genomes!$B:$B,0))) -> HE601899-squirrelpox_virus | J8: =INDEX(Genomes!$A:$A,(MATCH(AllProteins!H8,Genomes!$B:$B,0))) -> 48 | K8: =INDEX(Genomes!$J:$J,(MATCH(AllProteins!H8,Genomes!$B:$B,0))) -> Y
A9: =INDEX(CoreProteinGroups!A:A,MATCH(B9,CoreProteinGroups!B:B,0)) -> 1 | B9: A18 | C9: =VLOOKUP(B9,CoreProteinGroups!$B:$C,2,FALSE) -> DNA helicase | D9: ASK51316.1 | E9: =HYPERLINK(_xlfn.CONCAT("https://www.ncbi.nlm.nih.gov/protein/",D9),_xlfn.CONCAT("PROT:",D9)) -> PROT:ASK51316.1 | F9: DNA helicase, transcript release factor | G9: Eptesipox virus | H9: KY747497.1 | I9: =INDEX(Genomes!$I:$I,(MATCH(AllProteins!H9,Genomes!$B:$B,0))) -> KY747497-eptesipox_virus | J9: =INDEX(Genomes!$A:$A,(MATCH(AllProteins!H9,Genomes!$B:$B,0))) -> 19 | K9: =INDEX(Genomes!$J:$J,(MATCH(AllProteins!H9,Genomes!$B:$B,0))) -> Y
A10: =INDEX(CoreProteinGroups!A:A,MATCH(B10,CoreProteinGroups!B:B,0)) -> 1 | B10: A18 | C10: =VLOOKUP(B10,CoreProteinGroups!$B:$C,2,FALSE) -> DNA helicase | D10: AUD40291.1 | E10: =HYPERLINK(_xlfn.CONCAT("https://www.ncbi.nlm.nih.gov/protein/",D10),_xlfn.CONCAT("PROT:",D10)) -> PROT:AUD40291.1 | F10: DNA helicase | G10: Flamingopox virus FGPVKD09 | H10: MF678796.1 | I10: =INDEX(Genomes!$I:$I,(MATCH(AllProteins!H10,Genomes!$B:$B,0))) -> MF678796-flamingopox_virus | J10: =INDEX(Genomes!$A:$A,(MATCH(AllProteins!H10,Genomes!$B:$B,0))) -> 20 | K10: =INDEX(Genomes!$J:$J,(MATCH(AllProteins!H10,Genomes!$B:$B,0))) -> Y
A11: =INDEX(CoreProteinGroups!A:A,MATCH(B11,CoreProteinGroups!B:B,0)) -> 1 | B11: A18 | C11: =VLOOKUP(B11,CoreProteinGroups!$B:$C,2,FALSE) -> DNA helicase | D11: AID46922.1 | E11: =HYPERLINK(_xlfn.CONCAT("https://www.ncbi.nlm.nih.gov/protein/",D11),_xlfn.CONCAT("PROT:",D11)) -> PROT:AID46922.1 | F11: DNA helicase | G11: Penguinpox virus | H11: KJ859677.1 | I11: =INDEX(Genomes!$I:$I,(MATCH(AllProteins!H11,Genomes!$B:$B,0))) -> KJ859677-penguinpox_virus | J11: =INDEX(Genomes!$A:$A,(MATCH(AllProteins!H11,Genomes!$B:$B,0))) -> 39 | K11: =INDEX(Genomes!$J:$J,(MATCH(AllProteins!H11,Genomes!$B:$B,0))) -> Y
A12: =INDEX(CoreProteinGroups!A:A,MATCH(B12,CoreProteinGroups!B:B,0)) -> 1 | B12: A18 | C12: =VLOOKUP(B12,CoreProteinGroups!$B:$C,2,FALSE) -> DNA helicase | D12: AID46690.1 | E12: =HYPERLINK(_xlfn.CONCAT("https://www.ncbi.nlm.nih.gov/protein/",D12),_xlfn.CONCAT("PROT:",D12)) -> PROT:AID46690.1 | F12: DNA helicase | G12: Pigeonpox virus | H12: KJ801920.1 | I12: =INDEX(Genomes!$I:$I,(MATCH(AllProteins!H12,Genomes!$B:$B,0))) -> KJ801920-pigeonpox_virus | J12: =INDEX(Genomes!$A:$A,(MATCH(AllProteins!H12,Genomes!$B:$B,0))) -> 38 | K12: =INDEX(Genomes!$J:$J,(MATCH(AllProteins!H12,Genomes!$B:$B,0))) -> Y
A13: =INDEX(CoreProteinGroups!A:A,MATCH(B13,CoreProteinGroups!B:B,0)) -> 1 | B13: A18 | C13: =VLOOKUP(B13,CoreProteinGroups!$B:$C,2,FALSE) -> DNA helicase | D13: ALA62507.1 | E13: =HYPERLINK(_xlfn.CONCAT("https://www.ncbi.nlm.nih.gov/protein/",D13),_xlfn.CONCAT("PROT:",D13)) -> PROT:ALA62507.1 | F13: transcriptional elongation DNA helicase | G13: Turkeypox virus | H13: KP728110.2 | I13: =INDEX(Genomes!$I:$I,(MATCH(AllProteins!H13,Genomes!$B:$B,0))) -> KP728110-turkeypox_virus | J13: =INDEX(Genomes!$A:$A,(MATCH(AllProteins!H13,Genomes!$B:$B,0))) -> 51 | K13: =INDEX(Genomes!$J:$J,(MATCH(AllProteins!H13,Genomes!$B:$B,0))) -> Y
... A1451: =INDEX(CoreProteinGroups!A:A,MATCH(B1451,CoreProteinGroups!B:B,0)) -> 25 | B1451: L1 | C1451: =VLOOKUP(B1451,CoreProteinGroups!$B:$C,2,FALSE) -> IMV membrane protein | D1451: CCU56438.1 | E1451: =HYPERLINK(_xlfn.CONCAT("https://www.ncbi.nlm.nih.gov/protein/",D1451),_xlfn.CONCAT("PROT:",D1451)) -> PROT:CCU56438.1 | F1451: IMV membrane protein (Cop-L1R) | G1451: Mythimna separata entomopoxvirus 'L' | H1451: HF679134.1 | I1451: =INDEX(Genomes!$I:$I,(MATCH(AllProteins!H1451,Genomes!$B:$B,0))) -> HF679134-Mythimna_separata_entomopoxvirus | J1451: =INDEX(Genomes!$A:$A,(MATCH(AllProteins!H1451,Genomes!$B:$B,0))) -> 31 | K1451: =INDEX(Genomes!$J:$J,(MATCH(AllProteins!H1451,Genomes!$B:$B,0))) -> Y
A1452: =INDEX(CoreProteinGroups!A:A,MATCH(B1452,CoreProteinGroups!B:B,0)) -> 1 | B1452: A18 | C1452: =VLOOKUP(B1452,CoreProteinGroups!$B:$C,2,FALSE) -> DNA helicase | D1452: ATI21056.1 | E1452: =HYPERLINK(_xlfn.CONCAT("https://www.ncbi.nlm.nih.gov/protein/",D1452),_xlfn.CONCAT("PROT:",D1452)) -> PROT:ATI21056.1 | G1452: Western grey kangaroopox virus | H1452: MF467280.1 | I1452: =INDEX(Genomes!$I:$I,(MATCH(AllProteins!H1452,Genomes!$B:$B,0))) -> MF467280-Western_grey_kangaroopox_virus | J1452: =INDEX(Genomes!$A:$A,(MATCH(AllProteins!H1452,Genomes!$B:$B,0))) -> 56 | K1452: =INDEX(Genomes!$J:$J,(MATCH(AllProteins!H1452,Genomes!$B:$B,0))) -> Y
A1453: =INDEX(CoreProteinGroups!A:A,MATCH(B1453,CoreProteinGroups!B:B,0)) -> 2 | B1453: A22 | C1453: =VLOOKUP(B1453,CoreProteinGroups!$B:$C,2,FALSE) -> holliday junction resolvase | D1453: ATI21060.1 | E1453: =HYPERLINK(_xlfn.CONCAT("https://www.ncbi.nlm.nih.gov/protein/",D1453),_xlfn.CONCAT("PROT:",D1453)) -> PROT:ATI21060.1 | G1453: Western grey kangaroopox virus | H1453: MF467280.1 | I1453: =INDEX(Genomes!$I:$I,(MATCH(AllProteins!H1453,Genomes!$B:$B,0))) -> MF467280-Western_grey_kangaroopox_virus | J1453: =INDEX(Genomes!$A:$A,(MATCH(AllProteins!H1453,Genomes!$B:$B,0))) -> 56 | K1453: =INDEX(Genomes!$J:$J,(MATCH(AllProteins!H1453,Genomes!$B:$B,0))) -> Y
A1454: =INDEX(CoreProteinGroups!A:A,MATCH(B1454,CoreProteinGroups!B:B,0)) -> 3 | B1454: A23 | C1454: =VLOOKUP(B1454,CoreProteinGroups!$B:$C,2,FALSE) -> VITF-3 | D1454: ATI21061.1 | E1454: =HYPERLINK(_xlfn.CONCAT("https://www.ncbi.nlm.nih.gov/protein/",D1454),_xlfn.CONCAT("PROT:",D1454)) -> PROT:ATI21061.1 | G1454: Western grey kangaroopox virus | H1454: MF467280.1 | I1454: =INDEX(Genomes!$I:$I,(MATCH(AllProteins!H1454,Genomes!$B:$B,0))) -> MF467280-Western_grey_kangaroopox_virus | J1454: =INDEX(Genomes!$A:$A,(MATCH(AllProteins!H1454,Genomes!$B:$B,0))) -> 56 | K1454: =INDEX(Genomes!$J:$J,(MATCH(AllProteins!H1454,Genomes!$B:$B,0))) -> Y
A1455: =INDEX(CoreProteinGroups!A:A,MATCH(B1455,CoreProteinGroups!B:B,0)) -> 4 | B1455: A24 | C1455: =VLOOKUP(B1455,CoreProteinGroups!$B:$C,2,FALSE) -> RPO132 | D1455: ATI21062.1 | E1455: =HYPERLINK(_xlfn.CONCAT("https://www.ncbi.nlm.nih.gov/protein/",D1455),_xlfn.CONCAT("PROT:",D1455)) -> PROT:ATI21062.1 | G1455: Western grey kangaroopox virus | H1455: MF467280.1 | I1455: =INDEX(Genomes!$I:$I,(MATCH(AllProteins!H1455,Genomes!$B:$B,0))) -> MF467280-Western_grey_kangaroopox_virus | J1455: =INDEX(Genomes!$A:$A,(MATCH(AllProteins!H1455,Genomes!$B:$B,0))) -> 56 | K1455: =INDEX(Genomes!$J:$J,(MATCH(AllProteins!H1455,Genomes!$B:$B,0))) -> Y
A1456: =INDEX(CoreProteinGroups!A:A,MATCH(B1456,CoreProteinGroups!B:B,0)) -> 5 | B1456: A28 | C1456: =VLOOKUP(B1456,CoreProteinGroups!$B:$C,2,FALSE) -> IMV-MP | D1456: ATI21067.1 | E1456: =HYPERLINK(_xlfn.CONCAT("https://www.ncbi.nlm.nih.gov/protein/",D1456),_xlfn.CONCAT("PROT:",D1456)) -> PROT:ATI21067.1 | G1456: Western grey kangaroopox virus | H1456: MF467280.1 | I1456: =INDEX(Genomes!$I:$I,(MATCH(AllProteins!H1456,Genomes!$B:$B,0))) -> MF467280-Western_grey_kangaroopox_virus | J1456: =INDEX(Genomes!$A:$A,(MATCH(AllProteins!H1456,Genomes!$B:$B,0))) -> 56 | K1456: =INDEX(Genomes!$J:$J,(MATCH(AllProteins!H1456,Genomes!$B:$B,0))) -> Y
A1457: =INDEX(CoreProteinGroups!A:A,MATCH(B1457,CoreProteinGroups!B:B,0)) -> 6 | B1457: A2 | C1457: =VLOOKUP(B1457,CoreProteinGroups!$B:$C,2,FALSE) -> VLTF-3 | D1457: ATI21037.1 | E1457: =HYPERLINK(_xlfn.CONCAT("https://www.ncbi.nlm.nih.gov/protein/",D1457),_xlfn.CONCAT("PROT:",D1457)) -> PROT:ATI21037.1 | G1457: Western grey kangaroopox virus | H1457: MF467280.1 | I1457: =INDEX(Genomes!$I:$I,(MATCH(AllProteins!H1457,Genomes!$B:$B,0))) -> MF467280-Western_grey_kangaroopox_virus | J1457: =INDEX(Genomes!$A:$A,(MATCH(AllProteins!H1457,Genomes!$B:$B,0))) -> 56 | K1457: =INDEX(Genomes!$J:$J,(MATCH(AllProteins!H1457,Genomes!$B:$B,0))) -> Y
A1458: =INDEX(CoreProteinGroups!A:A,MATCH(B1458,CoreProteinGroups!B:B,0)) -> 7 | B1458: A32 | C1458: =VLOOKUP(B1458,CoreProteinGroups!$B:$C,2,FALSE) -> ATPase DNA packaging protein | D1458: ATI21073.1 | E1458: =HYPERLINK(_xlfn.CONCAT("https://www.ncbi.nlm.nih.gov/protein/",D1458),_xlfn.CONCAT("PROT:",D1458)) -> PROT:ATI21073.1 | G1458: Western grey kangaroopox virus | H1458: MF467280.1 | I1458: =INDEX(Genomes!$I:$I,(MATCH(AllProteins!H1458,Genomes!$B:$B,0))) -> MF467280-Western_grey_kangaroopox_virus | J1458: =INDEX(Genomes!$A:$A,(MATCH(AllProteins!H1458,Genomes!$B:$B,0))) -> 56 | K1458: =INDEX(Genomes!$J:$J,(MATCH(AllProteins!H1458,Genomes!$B:$B,0))) -> Y
A1459: =INDEX(CoreProteinGroups!A:A,MATCH(B1459,CoreProteinGroups!B:B,0)) -> 8 | B1459: A3 | C1459: =VLOOKUP(B1459,CoreProteinGroups!$B:$C,2,FALSE) -> P4b | D1459: ATI21039.1 | E1459: =HYPERLINK(_xlfn.CONCAT("https://www.ncbi.nlm.nih.gov/protein/",D1459),_xlfn.CONCAT("PROT:",D1459)) -> PROT:ATI21039.1 | G1459: Western grey kangaroopox virus | H1459: MF467280.1 | I1459: =INDEX(Genomes!$I:$I,(MATCH(AllProteins!H1459,Genomes!$B:$B,0))) -> MF467280-Western_grey_kangaroopox_virus | J1459: =INDEX(Genomes!$A:$A,(MATCH(AllProteins!H1459,Genomes!$B:$B,0))) -> 56 | K1459: =INDEX(Genomes!$J:$J,(MATCH(AllProteins!H1459,Genomes!$B:$B,0))) -> Y
A1460: =INDEX(CoreProteinGroups!A:A,MATCH(B1460,CoreProteinGroups!B:B,0)) -> 9 | B1460: A7 | C1460: =VLOOKUP(B1460,CoreProteinGroups!$B:$C,2,FALSE) -> VETF-L | D1460: ATI21043.1 | E1460: =HYPERLINK(_xlfn.CONCAT("https://www.ncbi.nlm.nih.gov/protein/",D1460),_xlfn.CONCAT("PROT:",D1460)) -> PROT:ATI21043.1 | G1460: Western grey kangaroopox virus | H1460: MF467280.1 | I1460: =INDEX(Genomes!$I:$I,(MATCH(AllProteins!H1460,Genomes!$B:$B,0))) -> MF467280-Western_grey_kangaroopox_virus | J1460: =INDEX(Genomes!$A:$A,(MATCH(AllProteins!H1460,Genomes!$B:$B,0))) -> 56 | K1460: =INDEX(Genomes!$J:$J,(MATCH(AllProteins!H1460,Genomes!$B:$B,0))) -> Y
A1461: =INDEX(CoreProteinGroups!A:A,MATCH(B1461,CoreProteinGroups!B:B,0)) -> 10 | B1461: D11 | C1461: =VLOOKUP(B1461,CoreProteinGroups!$B:$C,2,FALSE) -> NPH-I | D1461: ATI21033.1 | E1461: =HYPERLINK(_xlfn.CONCAT("https://www.ncbi.nlm.nih.gov/protein/",D1461),_xlfn.CONCAT("PROT:",D1461)) -> PROT:ATI21033.1 | G1461: Western grey kangaroopox virus | H1461: MF467280.1 | I1461: =INDEX(Genomes!$I:$I,(MATCH(AllProteins!H1461,Genomes!$B:$B,0))) -> MF467280-Western_grey_kangaroopox_virus | J1461: =INDEX(Genomes!$A:$A,(MATCH(AllProteins!H1461,Genomes!$B:$B,0))) -> 56 | K1461: =INDEX(Genomes!$J:$J,(MATCH(AllProteins!H1461,Genomes!$B:$B,0))) -> Y
A1462: =INDEX(CoreProteinGroups!A:A,MATCH(B1462,CoreProteinGroups!B:B,0)) -> 11 | B1462: D12 | C1462: =VLOOKUP(B1462,CoreProteinGroups!$B:$C,2,FALSE) -> small capping enzyme | D1462: ATI21034.1 | E1462: =HYPERLINK(_xlfn.CONCAT("https://www.ncbi.nlm.nih.gov/protein/",D1462),_xlfn.CONCAT("PROT:",D1462)) -> PROT:ATI21034.1 | G1462: Western grey kangaroopox virus | H1462: MF467280.1 | I1462: =INDEX(Genomes!$I:$I,(MATCH(AllProteins!H1462,Genomes!$B:$B,0))) -> MF467280-Western_grey_kangaroopox_virus | J1462: =INDEX(Genomes!$A:$A,(MATCH(AllProteins!H1462,Genomes!$B:$B,0))) -> 56 | K1462: =INDEX(Genomes!$J:$J,(MATCH(AllProteins!H1462,Genomes!$B:$B,0))) -> Y
A1463: =INDEX(CoreProteinGroups!A:A,MATCH(B1463,CoreProteinGroups!B:B,0)) -> 12 | B1463: D1 | C1463: =VLOOKUP(B1463,CoreProteinGroups!$B:$C,2,FALSE) -> large capping enzyme | D1463: ATI21024.1 | E1463: =HYPERLINK(_xlfn.CONCAT("https://www.ncbi.nlm.nih.gov/protein/",D1463),_xlfn.CONCAT("PROT:",D1463)) -> PROT:ATI21024.1 | G1463: Western grey kangaroopox virus | H1463: MF467280.1 | I1463: =INDEX(Genomes!$I:$I,(MATCH(AllProteins!H1463,Genomes!$B:$B,0))) -> MF467280-Western_grey_kangaroopox_virus | J1463: =INDEX(Genomes!$A:$A,(MATCH(AllProteins!H1463,Genomes!$B:$B,0))) -> 56 | K1463: =INDEX(Genomes!$J:$J,(MATCH(AllProteins!H1463,Genomes!$B:$B,0))) -> Y
... A1501: =INDEX(CoreProteinGroups!A:A,MATCH(B1501,CoreProteinGroups!B:B,0)) -> 25 | B1501: L1 | C1501: =VLOOKUP(B1501,CoreProteinGroups!$B:$C,2,FALSE) -> IMV membrane protein | D1501: YDH75346.1 | E1501: =HYPERLINK(_xlfn.CONCAT("https://www.ncbi.nlm.nih.gov/protein/",D1501),_xlfn.CONCAT("PROT:",D1501)) -> PROT:YDH75346.1 | G1501: Madamurpox virus | H1501: PZ016454.1 | I1501: =INDEX(Genomes!$I:$I,(MATCH(AllProteins!H1501,Genomes!$B:$B,0))) -> PZ016454-Madamurpox_virus | J1501: =INDEX(Genomes!$A:$A,(MATCH(AllProteins!H1501,Genomes!$B:$B,0))) -> 60 | K1501: =INDEX(Genomes!$J:$J,(MATCH(AllProteins!H1501,Genomes!$B:$B,0))) -> Y
A1502: =INDEX(CoreProteinGroups!A:A,MATCH(B1502,CoreProteinGroups!B:B,0)) -> 1 | B1502: A18 | C1502: =VLOOKUP(B1502,CoreProteinGroups!$B:$C,2,FALSE) -> DNA helicase | D1502: XBH23847.1 | E1502: =HYPERLINK(_xlfn.CONCAT("https://www.ncbi.nlm.nih.gov/protein/",D1502),_xlfn.CONCAT("PROT:",D1502)) -> PROT:XBH23847.1 | F1502: DNA helicase | G1502: Rousettus bat poxvirus isolate 1A/Uganda/UGR70/2019 | H1502: PP711852.1 | I1502: =INDEX(Genomes!$I:$I,(MATCH(AllProteins!H1502,Genomes!$B:$B,0))) -> PP711852-rousettus_bat_poxvirus | J1502: =INDEX(Genomes!$A:$A,(MATCH(AllProteins!H1502,Genomes!$B:$B,0))) -> 61 | K1502: =INDEX(Genomes!$J:$J,(MATCH(AllProteins!H1502,Genomes!$B:$B,0))) -> Y
A1503: =INDEX(CoreProteinGroups!A:A,MATCH(B1503,CoreProteinGroups!B:B,0)) -> 2 | B1503: A22 | C1503: =VLOOKUP(B1503,CoreProteinGroups!$B:$C,2,FALSE) -> holliday junction resolvase | D1503: XBH23851.1 | E1503: =HYPERLINK(_xlfn.CONCAT("https://www.ncbi.nlm.nih.gov/protein/",D1503),_xlfn.CONCAT("PROT:",D1503)) -> PROT:XBH23851.1 | F1503: holliday junction resolvase | G1503: Rousettus bat poxvirus isolate 1A/Uganda/UGR70/2019 | H1503: PP711852.1 | I1503: =INDEX(Genomes!$I:$I,(MATCH(AllProteins!H1503,Genomes!$B:$B,0))) -> PP711852-rousettus_bat_poxvirus | J1503: =INDEX(Genomes!$A:$A,(MATCH(AllProteins!H1503,Genomes!$B:$B,0))) -> 61 | K1503: =INDEX(Genomes!$J:$J,(MATCH(AllProteins!H1503,Genomes!$B:$B,0))) -> Y
A1504: =INDEX(CoreProteinGroups!A:A,MATCH(B1504,CoreProteinGroups!B:B,0)) -> 3 | B1504: A23 | C1504: =VLOOKUP(B1504,CoreProteinGroups!$B:$C,2,FALSE) -> VITF-3 | D1504: XBH23852.1 | E1504: =HYPERLINK(_xlfn.CONCAT("https://www.ncbi.nlm.nih.gov/protein/",D1504),_xlfn.CONCAT("PROT:",D1504)) -> PROT:XBH23852.1 | F1504: intermediate transcription factor VITF-3 | G1504: Rousettus bat poxvirus isolate 1A/Uganda/UGR70/2019 | H1504: PP711852.1 | I1504: =INDEX(Genomes!$I:$I,(MATCH(AllProteins!H1504,Genomes!$B:$B,0))) -> PP711852-rousettus_bat_poxvirus | J1504: =INDEX(Genomes!$A:$A,(MATCH(AllProteins!H1504,Genomes!$B:$B,0))) -> 61 | K1504: =INDEX(Genomes!$J:$J,(MATCH(AllProteins!H1504,Genomes!$B:$B,0))) -> Y
A1505: =INDEX(CoreProteinGroups!A:A,MATCH(B1505,CoreProteinGroups!B:B,0)) -> 4 | B1505: A24 | C1505: =VLOOKUP(B1505,CoreProteinGroups!$B:$C,2,FALSE) -> RPO132 | D1505: XBH23853.1 | E1505: =HYPERLINK(_xlfn.CONCAT("https://www.ncbi.nlm.nih.gov/protein/",D1505),_xlfn.CONCAT("PROT:",D1505)) -> PROT:XBH23853.1 | F1505: DNA-dependent RNA polymerase subunit rpo132 | G1505: Rousettus bat poxvirus isolate 1A/Uganda/UGR70/2019 | H1505: PP711852.1 | I1505: =INDEX(Genomes!$I:$I,(MATCH(AllProteins!H1505,Genomes!$B:$B,0))) -> PP711852-rousettus_bat_poxvirus | J1505: =INDEX(Genomes!$A:$A,(MATCH(AllProteins!H1505,Genomes!$B:$B,0))) -> 61 | K1505: =INDEX(Genomes!$J:$J,(MATCH(AllProteins!H1505,Genomes!$B:$B,0))) -> Y
A1506: =INDEX(CoreProteinGroups!A:A,MATCH(B1506,CoreProteinGroups!B:B,0)) -> 5 | B1506: A28 | C1506: =VLOOKUP(B1506,CoreProteinGroups!$B:$C,2,FALSE) -> IMV-MP | D1506: XBH23857.1 | E1506: =HYPERLINK(_xlfn.CONCAT("https://www.ncbi.nlm.nih.gov/protein/",D1506),_xlfn.CONCAT("PROT:",D1506)) -> PROT:XBH23857.1 | F1506: hypothetical protein | G1506: Rousettus bat poxvirus isolate 1A/Uganda/UGR70/2019 | H1506: PP711852.1 | I1506: =INDEX(Genomes!$I:$I,(MATCH(AllProteins!H1506,Genomes!$B:$B,0))) -> PP711852-rousettus_bat_poxvirus | J1506: =INDEX(Genomes!$A:$A,(MATCH(AllProteins!H1506,Genomes!$B:$B,0))) -> 61 | K1506: =INDEX(Genomes!$J:$J,(MATCH(AllProteins!H1506,Genomes!$B:$B,0))) -> Y
A1507: =INDEX(CoreProteinGroups!A:A,MATCH(B1507,CoreProteinGroups!B:B,0)) -> 6 | B1507: A2 | C1507: =VLOOKUP(B1507,CoreProteinGroups!$B:$C,2,FALSE) -> VLTF-3 | D1507: XBH23832.1 | E1507: =HYPERLINK(_xlfn.CONCAT("https://www.ncbi.nlm.nih.gov/protein/",D1507),_xlfn.CONCAT("PROT:",D1507)) -> PROT:XBH23832.1 | F1507: late transcription factor VLTF-3 | G1507: Rousettus bat poxvirus isolate 1A/Uganda/UGR70/2019 | H1507: PP711852.1 | I1507: =INDEX(Genomes!$I:$I,(MATCH(AllProteins!H1507,Genomes!$B:$B,0))) -> PP711852-rousettus_bat_poxvirus | J1507: =INDEX(Genomes!$A:$A,(MATCH(AllProteins!H1507,Genomes!$B:$B,0))) -> 61 | K1507: =INDEX(Genomes!$J:$J,(MATCH(AllProteins!H1507,Genomes!$B:$B,0))) -> Y
A1508: =INDEX(CoreProteinGroups!A:A,MATCH(B1508,CoreProteinGroups!B:B,0)) -> 7 | B1508: A32 | C1508: =VLOOKUP(B1508,CoreProteinGroups!$B:$C,2,FALSE) -> ATPase DNA packaging protein | D1508: XBH23862.1 | E1508: =HYPERLINK(_xlfn.CONCAT("https://www.ncbi.nlm.nih.gov/protein/",D1508),_xlfn.CONCAT("PROT:",D1508)) -> PROT:XBH23862.1 | F1508: ATPase/DNA packaging protein | G1508: Rousettus bat poxvirus isolate 1A/Uganda/UGR70/2019 | H1508: PP711852.1 | I1508: =INDEX(Genomes!$I:$I,(MATCH(AllProteins!H1508,Genomes!$B:$B,0))) -> PP711852-rousettus_bat_poxvirus | J1508: =INDEX(Genomes!$A:$A,(MATCH(AllProteins!H1508,Genomes!$B:$B,0))) -> 61 | K1508: =INDEX(Genomes!$J:$J,(MATCH(AllProteins!H1508,Genomes!$B:$B,0))) -> Y
A1509: =INDEX(CoreProteinGroups!A:A,MATCH(B1509,CoreProteinGroups!B:B,0)) -> 8 | B1509: A3 | C1509: =VLOOKUP(B1509,CoreProteinGroups!$B:$C,2,FALSE) -> P4b | D1509: XBH23834.1 | E1509: =HYPERLINK(_xlfn.CONCAT("https://www.ncbi.nlm.nih.gov/protein/",D1509),_xlfn.CONCAT("PROT:",D1509)) -> PROT:XBH23834.1 | F1509: P4b precursor | G1509: Rousettus bat poxvirus isolate 1A/Uganda/UGR70/2019 | H1509: PP711852.1 | I1509: =INDEX(Genomes!$I:$I,(MATCH(AllProteins!H1509,Genomes!$B:$B,0))) -> PP711852-rousettus_bat_poxvirus | J1509: =INDEX(Genomes!$A:$A,(MATCH(AllProteins!H1509,Genomes!$B:$B,0))) -> 61 | K1509: =INDEX(Genomes!$J:$J,(MATCH(AllProteins!H1509,Genomes!$B:$B,0))) -> Y
A1510: =INDEX(CoreProteinGroups!A:A,MATCH(B1510,CoreProteinGroups!B:B,0)) -> 9 | B1510: A7 | C1510: =VLOOKUP(B1510,CoreProteinGroups!$B:$C,2,FALSE) -> VETF-L | D1510: PP711852.1-A7 | E1510: =HYPERLINK(_xlfn.CONCAT("https://www.ncbi.nlm.nih.gov/protein/",D1510),_xlfn.CONCAT("PROT:",D1510)) -> PROT:PP711852.1-A7 | F1510: NOT ANNOTATED (tblastn-2sequences) | G1510: Rousettus bat poxvirus isolate 1A/Uganda/UGR70/2019 | H1510: PP711852.1 | I1510: =INDEX(Genomes!$I:$I,(MATCH(AllProteins!H1510,Genomes!$B:$B,0))) -> PP711852-rousettus_bat_poxvirus | J1510: =INDEX(Genomes!$A:$A,(MATCH(AllProteins!H1510,Genomes!$B:$B,0))) -> 61 | K1510: =INDEX(Genomes!$J:$J,(MATCH(AllProteins!H1510,Genomes!$B:$B,0))) -> Y
A1511: =INDEX(CoreProteinGroups!A:A,MATCH(B1511,CoreProteinGroups!B:B,0)) -> 10 | B1511: D11 | C1511: =VLOOKUP(B1511,CoreProteinGroups!$B:$C,2,FALSE) -> NPH-I | D1511: PP711852.1-D11 | E1511: =HYPERLINK(_xlfn.CONCAT("https://www.ncbi.nlm.nih.gov/protein/",D1511),_xlfn.CONCAT("PROT:",D1511)) -> PROT:PP711852.1-D11 | F1511: NOT ANNOTATED (tblastn-2sequences) | G1511: Rousettus bat poxvirus isolate 1A/Uganda/UGR70/2019 | H1511: PP711852.1 | I1511: =INDEX(Genomes!$I:$I,(MATCH(AllProteins!H1511,Genomes!$B:$B,0))) -> PP711852-rousettus_bat_poxvirus | J1511: =INDEX(Genomes!$A:$A,(MATCH(AllProteins!H1511,Genomes!$B:$B,0))) -> 61 | K1511: =INDEX(Genomes!$J:$J,(MATCH(AllProteins!H1511,Genomes!$B:$B,0))) -> Y
A1512: =INDEX(CoreProteinGroups!A:A,MATCH(B1512,CoreProteinGroups!B:B,0)) -> 11 | B1512: D12 | C1512: =VLOOKUP(B1512,CoreProteinGroups!$B:$C,2,FALSE) -> small capping enzyme | D1512: XBH23830.1 | E1512: =HYPERLINK(_xlfn.CONCAT("https://www.ncbi.nlm.nih.gov/protein/",D1512),_xlfn.CONCAT("PROT:",D1512)) -> PROT:XBH23830.1 | F1512: mRNA capping enzyme small subunit | G1512: Rousettus bat poxvirus isolate 1A/Uganda/UGR70/2019 | H1512: PP711852.1 | I1512: =INDEX(Genomes!$I:$I,(MATCH(AllProteins!H1512,Genomes!$B:$B,0))) -> PP711852-rousettus_bat_poxvirus | J1512: =INDEX(Genomes!$A:$A,(MATCH(AllProteins!H1512,Genomes!$B:$B,0))) -> 61 | K1512: =INDEX(Genomes!$J:$J,(MATCH(AllProteins!H1512,Genomes!$B:$B,0))) -> Y
A1513: =INDEX(CoreProteinGroups!A:A,MATCH(B1513,CoreProteinGroups!B:B,0)) -> 12 | B1513: D1 | C1513: =VLOOKUP(B1513,CoreProteinGroups!$B:$C,2,FALSE) -> large capping enzyme | D1513: XBH23825.1 | E1513: =HYPERLINK(_xlfn.CONCAT("https://www.ncbi.nlm.nih.gov/protein/",D1513),_xlfn.CONCAT("PROT:",D1513)) -> PROT:XBH23825.1 | F1513: mRNA capping enzyme large subunit | G1513: Rousettus bat poxvirus isolate 1A/Uganda/UGR70/2019 | H1513: PP711852.1 | I1513: =INDEX(Genomes!$I:$I,(MATCH(AllProteins!H1513,Genomes!$B:$B,0))) -> PP711852-rousettus_bat_poxvirus | J1513: =INDEX(Genomes!$A:$A,(MATCH(AllProteins!H1513,Genomes!$B:$B,0))) -> 61 | K1513: =INDEX(Genomes!$J:$J,(MATCH(AllProteins!H1513,Genomes!$B:$B,0))) -> Y
... A1551: =INDEX(CoreProteinGroups!A:A,MATCH(B1551,CoreProteinGroups!B:B,0)) -> 25 | B1551: L1 | C1551: =VLOOKUP(B1551,CoreProteinGroups!$B:$C,2,FALSE) -> IMV membrane protein | D1551: AAA48076.1 | E1551: =HYPERLINK(_xlfn.CONCAT("https://www.ncbi.nlm.nih.gov/protein/",D1551),_xlfn.CONCAT("PROT:",D1551)) -> PROT:AAA48076.1 | F1551: IMV membrane protein | G1551: Vaccinia virus Copenhagen | H1551: M35027.1 | I1551: =INDEX(Genomes!$I:$I,(MATCH(AllProteins!H1551,Genomes!$B:$B,0))) -> M35027-vaccinia_virus_strain_Copenhagen | J1551: =INDEX(Genomes!$A:$A,(MATCH(AllProteins!H1551,Genomes!$B:$B,0))) -> 62 | K1551: =INDEX(Genomes!$J:$J,(MATCH(AllProteins!H1551,Genomes!$B:$B,0))) -> N

Sheet Genomes
A1: GenomeOrder | B1: IsolateAccession | C1: GenomeLink | D1: IsolateName | E1: AccInAllProteins | F1: ICTV_Fig4 | G1: proteinAlign | H1: BaseAccession | I1: GenomeDisplayName | J1: inNewPoxAlign
A2: 1 | B2: MH816996.1 | C2: =HYPERLINK(_xlfn.CONCAT("https://www.ncbi.nlm.nih.gov/nuccore/",B2),B2) -> MH816996.1 | D2: Orthopoxvirus Abatino | E2: =MATCH(C2,AllProteins!$H:$H,0) -> 25 | F2: Y | G2: Y | I2: MH816996-orthopoxvirus_abatino | J2: Y
A3: 2 | B3: AP013055.1 | C3: =HYPERLINK(_xlfn.CONCAT("https://www.ncbi.nlm.nih.gov/nuccore/",B3),B3) -> AP013055.1 | D3: Anomala cuprea entomopoxvirus | E3: =MATCH(C3,AllProteins!$H:$H,0) -> 52 | F3: Y | G3: Y | I3: AP013055-Anomala_cuprea_entomopoxvirus | J3: Y
A4: 3 | B4: HF679131.1 | C4: =HYPERLINK(_xlfn.CONCAT("https://www.ncbi.nlm.nih.gov/nuccore/",B4),B4) -> HF679131.1 | D4: Adoxophyes honmai entomopoxvirus 'L' | E4: =MATCH(C4,AllProteins!$H:$H,0) -> 53 | F4: Y | G4: Y | I4: HF679131-Adoxophyes_honmai_entomopoxvirus | J4: Y
A5: 4 | B5: MH607141.1 | C5: =HYPERLINK(_xlfn.CONCAT("https://www.ncbi.nlm.nih.gov/nuccore/",B5),B5) -> MH607141.1 | D5: Akhmeta virus | E5: =MATCH(C5,AllProteins!$H:$H,0) -> 26 | F5: Y | G5: Y | I5: MH607141-Akhmeta_virus | J5: Y
A6: 5 | B6: AF250284.1 | C6: =HYPERLINK(_xlfn.CONCAT("https://www.ncbi.nlm.nih.gov/nuccore/",B6),B6) -> AF250284.1 | D6: Amsacta moorei entomopoxvirus | E6: =MATCH(C6,AllProteins!$H:$H,0) -> 54 | F6: Y | G6: Y | I6: AF250284-Amsacta_moorei_entomopoxvirus | J6: Y
A7: 6 | B7: AY386265.1 | C7: =HYPERLINK(_xlfn.CONCAT("https://www.ncbi.nlm.nih.gov/nuccore/",B7),B7) -> AY386265.1 | D7: Bovine papular stomatitis virus | E7: =MATCH(C7,AllProteins!$H:$H,0) -> 43 | F7: Y | G7: Y | I7: AY386265-bovine_papular_stomatitis_virus | J7: Y
A8: 7 | B8: KY094066.1 | C8: =HYPERLINK(_xlfn.CONCAT("https://www.ncbi.nlm.nih.gov/nuccore/",B8),B8) -> KY094066.1 | D8: BeAn 58058 virus | E8: =MATCH(C8,AllProteins!$H:$H,0) -> 4 | F8: N | G8: Y | I8: KY094066-BeAn_58058_virus | J8: N
A9: 8 | B9: AF438165.1 | C9: =HYPERLINK(_xlfn.CONCAT("https://www.ncbi.nlm.nih.gov/nuccore/",B9),B9) -> AF438165.1 | D9: Camelpox virus M-96 | E9: =MATCH(C9,AllProteins!$H:$H,0) -> 29 | F9: Y | G9: Y | I9: AF438165-camelpox_virus | J9: Y
A10: 9 | B10: AY009089.1 | C10: =HYPERLINK(_xlfn.CONCAT("https://www.ncbi.nlm.nih.gov/nuccore/",B10),B10) -> AY009089.1 | D10: Camelpox virus CMS | E10: =MATCH(C10,AllProteins!$H:$H,0) -> 28 | F10: N | G10: Y | I10: AY009089-camelpox_virus_CMS | J10: N
A11: 10 | B11: HF679132.1 | C11: =HYPERLINK(_xlfn.CONCAT("https://www.ncbi.nlm.nih.gov/nuccore/",B11),B11) -> HF679132.1 | D11: Choristoneura biennis entomopoxvirus | E11: =MATCH(C11,AllProteins!$H:$H,0) -> 55 | F11: Y | G11: Y | I11: HF679132-Choristoneura_biennis_entomopoxvirus | J11: Y
A12: 11 | B12: AY318871.1 | C12: =HYPERLINK(_xlfn.CONCAT("https://www.ncbi.nlm.nih.gov/nuccore/",B12),B12) -> AY318871.1 | D12: Canarypox virus | E12: =MATCH(C12,AllProteins!$H:$H,0) -> 14 | F12: Y | G12: Y | I12: AY318871-canarypox_virus | J12: Y
A13: 12 | B13: HQ647181.2 | C13: =HYPERLINK(_xlfn.CONCAT("https://www.ncbi.nlm.nih.gov/nuccore/",B13),B13) -> HQ647181.2 | D13: Cotia virus SPAn232 | E13: =MATCH(C13,AllProteins!$H:$H,0) -> 5 | F13: Y | G13: Y | I13: HQ647181-Cotia_virus | J13: Y
... A23: 22 | B23: KY382358.2 | C23: =HYPERLINK(_xlfn.CONCAT("https://www.ncbi.nlm.nih.gov/nuccore/",B23),B23) -> KY382358.2 | D23: Seal parapoxvirus | E23: =MATCH(C23,AllProteins!$H:$H,0) -> 42 | F23: Y | G23: Y | I23: KY382358-seal_parapoxvirus | J23: Y
A24: 23 | B24: NC_004003.1 | C24: =HYPERLINK(_xlfn.CONCAT("https://www.ncbi.nlm.nih.gov/nuccore/",B24),B24) -> NC_004003.1 | D24: Goatpox virus Pellor | E24: =MATCH(C24,AllProteins!$H:$H,0) -> 59 | F24: Y | G24: Y | H24: AY077835.1 | I24: NC_004003-goatpox_virus | J24: Y
A25: 24 | B25: DQ792504.1 | C25: =HYPERLINK(_xlfn.CONCAT("https://www.ncbi.nlm.nih.gov/nuccore/",B25),B25) -> DQ792504.1 | D25: Horsepox virus | E25: =MATCH(C25,AllProteins!$H:$H,0) -> 27 | F25: Y | G25: Y | I25: DQ792504-horsepox_virus | J25: Y
A26: 25 | B26: AF325528.1 | C26: =HYPERLINK(_xlfn.CONCAT("https://www.ncbi.nlm.nih.gov/nuccore/",B26),B26) -> AF325528.1 | D26: Lumpy skin disease virus NI-2490 | E26: =MATCH(C26,AllProteins!$H:$H,0) -> 16 | F26: Y | G26: Y | I26: AF325528-lumpy_skin_disease_virus | J26: Y
A27: 26 | B27: U60315.1 | C27: =HYPERLINK(_xlfn.CONCAT("https://www.ncbi.nlm.nih.gov/nuccore/",B27),B27) -> U60315.1 | D27: Molluscum contagiosum virus subtype 1 | E27: =MATCH(C27,AllProteins!$H:$H,0) -> 24 | F27: Y | G27: Y | I27: U60315-molluscum_contagiosum_virus | J27: Y
A28: 27 | B28: MF001304.1 | C28: =HYPERLINK(_xlfn.CONCAT("https://www.ncbi.nlm.nih.gov/nuccore/",B28),B28) -> MF001304.1 | D28: Murmansk poxvirus | E28: =MATCH(C28,AllProteins!$H:$H,0) -> 17 | F28: Y | G28: Y | I28: MF001304-Murmansk_poxvirus | J28: Y
A29: 28 | B29: AY753185.1 | C29: =HYPERLINK(_xlfn.CONCAT("https://www.ncbi.nlm.nih.gov/nuccore/",B29),B29) -> AY753185.1 | D29: monkeypox virus strain cOP-58 (clade IIa) | E29: =MATCH(C29,AllProteins!$H:$H,0) -> 34 | F29: Y | G29: Y | I29: AY753185-monkeypox_virus_(clade_IIa) | J29: Y
A30: 29 | B30: AF380138.1 | C30: =HYPERLINK(_xlfn.CONCAT("https://www.ncbi.nlm.nih.gov/nuccore/",B30),B30) -> AF380138.1 | D30: Monkeypox virus Zaire-96-I-16 (clade I) | E30: =MATCH(C30,AllProteins!$H:$H,0) -> 33 | F30: Y | G30: Y | I30: AF380138-monkeypox_virus_(clade_I) | J30: Y
A31: 30 | B31: AF063866.1 | C31: =HYPERLINK(_xlfn.CONCAT("https://www.ncbi.nlm.nih.gov/nuccore/",B31),B31) -> AF063866.1 | D31: Melanoplus sanguinipes entomopoxvirus 'O' | E31: =MATCH(C31,AllProteins!$H:$H,0) -> 51 | F31: Y | G31: Y | I31: AF063866-Melanoplus_sanguinipes_entomopoxvirus | J31: Y
A32: 31 | B32: HF679134.1 | C32: =HYPERLINK(_xlfn.CONCAT("https://www.ncbi.nlm.nih.gov/nuccore/",B32),B32) -> HF679134.1 | D32: Mythimna separata entomopoxvirus 'L' | E32: =MATCH(C32,AllProteins!$H:$H,0) -> 57 | F32: Y | G32: Y | I32: HF679134-Mythimna_separata_entomopoxvirus | J32: Y
A33: 32 | B33: AF170726.2 | C33: =HYPERLINK(_xlfn.CONCAT("https://www.ncbi.nlm.nih.gov/nuccore/",B33),B33) -> AF170726.2 | D33: Myxoma virus strain Lausanne | E33: =MATCH(C33,AllProteins!$H:$H,0) -> 21 | F33: Y | G33: Y | I33: AF170726-myxoma_virus | J33: Y
A34: 33 | B34: JX565564.1 | C34: =HYPERLINK(_xlfn.CONCAT("https://www.ncbi.nlm.nih.gov/nuccore/",B34),B34) -> JX565564.1 | D34: Myxoma virus isolate BRK 897 | E34: =MATCH(C34,AllProteins!$H:$H,0) -> 22 | F34: Y | G34: Y | I34: JX565564-myxoma_virus_isolate_BRK_897 | J34: N
A35: 34 | B35: DQ356948.1 | C35: =HYPERLINK(_xlfn.CONCAT("https://www.ncbi.nlm.nih.gov/nuccore/",B35),B35) -> DQ356948.1 | D35: Nile crocodilepox virus | E35: =MATCH(C35,AllProteins!$H:$H,0) -> 20 | F35: Y | G35: Y | I35: DQ356948-Nile_crocodilepox_virus | J35: Y
A36: 35 | B36: AY386264.1 | C36: =HYPERLINK(_xlfn.CONCAT("https://www.ncbi.nlm.nih.gov/nuccore/",B36),B36) -> AY386264.1 | D36: Orf virus strain OV-SA00 | E36: =MATCH(C36,AllProteins!$H:$H,0) -> 44 | F36: N | G36: Y | I36: AY386264-orf_virus | J36: Y
... A44: 43 | B44: AF170722.1 | C44: =HYPERLINK(_xlfn.CONCAT("https://www.ncbi.nlm.nih.gov/nuccore/",B44),B44) -> AF170722.1 | D44: Rabbit fibroma virus | E44: =MATCH(C44,AllProteins!$H:$H,0) -> 23 | F44: Y | G44: Y | I44: AF170722-rabbit_fibroma_virus | J44: Y
A45: 44 | B45: NC_004002.1 | C45: =HYPERLINK(_xlfn.CONCAT("https://www.ncbi.nlm.nih.gov/nuccore/",B45),B45) -> NC_004002.1 | D45: Sheeppox virus | E45: =MATCH(C45,AllProteins!$H:$H,0) -> 58 | F45: Y | G45: Y | H45: AY077832.1 | I45: NC_004002-sheeppox_virus | J45: Y
A46: 45 | B46: KU749310.1 | C46: =HYPERLINK(_xlfn.CONCAT("https://www.ncbi.nlm.nih.gov/nuccore/",B46),B46) -> KU749310.1 | D46: Skunkpox virus | E46: =MATCH(C46,AllProteins!$H:$H,0) -> 36 | F46: Y | G46: Y | I46: KU749310-skunkpox_virus | J46: Y
A47: 46 | B47: KT159937.1 | C47: =HYPERLINK(_xlfn.CONCAT("https://www.ncbi.nlm.nih.gov/nuccore/",B47),B47) -> KT159937.1 | D47: Salmon gill poxvirus | E47: =MATCH(C47,AllProteins!$H:$H,0) -> 7 | F47: Y | G47: Y | I47: KT159937-salmon_gill_poxvirus | J47: Y
A48: 47 | B48: MH427217.1 | C48: =HYPERLINK(_xlfn.CONCAT("https://www.ncbi.nlm.nih.gov/nuccore/",B48),B48) -> MH427217.1 | D48: Sea otter poxvirus | E48: =MATCH(C48,AllProteins!$H:$H,0) -> 3 | F48: Y | G48: Y | I48: MH427217-sea_otter_poxvirus | J48: Y
A49: 48 | B49: HE601899.1 | C49: =HYPERLINK(_xlfn.CONCAT("https://www.ncbi.nlm.nih.gov/nuccore/",B49),B49) -> HE601899.1 | D49: Squirrelpox virus | E49: =MATCH(C49,AllProteins!$H:$H,0) -> 8 | F49: Y | G49: Y | I49: HE601899-squirrelpox_virus | J49: Y
A50: 49 | B50: AF410153.1 | C50: =HYPERLINK(_xlfn.CONCAT("https://www.ncbi.nlm.nih.gov/nuccore/",B50),B50) -> AF410153.1 | D50: Swinepox virus | E50: =MATCH(C50,AllProteins!$H:$H,0) -> 48 | F50: Y | G50: Y | I50: AF410153-swinepox_virus | J50: Y
A51: 50 | B51: DQ437594.1 | C51: =HYPERLINK(_xlfn.CONCAT("https://www.ncbi.nlm.nih.gov/nuccore/",B51),B51) -> DQ437594.1 | D51: Taterapox virus | E51: =MATCH(C51,AllProteins!$H:$H,0) -> 37 | F51: Y | G51: Y | I51: DQ437594-taterapox_virus | J51: Y
A52: 51 | B52: KP728110.2 | C52: =HYPERLINK(_xlfn.CONCAT("https://www.ncbi.nlm.nih.gov/nuccore/",B52),B52) -> KP728110.2 | D52: Turkeypox virus | E52: =MATCH(C52,AllProteins!$H:$H,0) -> 13 | F52: Y | G52: Y | I52: KP728110-turkeypox_virus | J52: Y
A53: 52 | B53: AY243312.1 | C53: =HYPERLINK(_xlfn.CONCAT("https://www.ncbi.nlm.nih.gov/nuccore/",B53),B53) -> AY243312.1 | D53: Vaccinia virus WR | E53: =MATCH(C53,AllProteins!$H:$H,0) -> 38 | F53: Y | G53: Y | I53: AY243312-vaccinia_virus | J53: Y
A54: 53 | B54: X69198.1 | C54: =HYPERLINK(_xlfn.CONCAT("https://www.ncbi.nlm.nih.gov/nuccore/",B54),B54) -> X69198.1 | D54: Variola virus major | E54: =MATCH(C54,AllProteins!$H:$H,0) -> 39 | F54: Y | G54: Y | I54: X69198-variola_major_virus | J54: Y
A55: 54 | B55: Y16780.1 | C55: =HYPERLINK(_xlfn.CONCAT("https://www.ncbi.nlm.nih.gov/nuccore/",B55),B55) -> Y16780.1 | D55: Variola minor virus | E55: =MATCH(C55,AllProteins!$H:$H,0) -> 40 | F55: Y | G55: Y | I55: Y16780-variola_minor_virus | J55: Y
A56: 55 | B56: KU749311.1 | C56: =HYPERLINK(_xlfn.CONCAT("https://www.ncbi.nlm.nih.gov/nuccore/",B56),B56) -> KU749311.1 | D56: Volepox virus | E56: =MATCH(C56,AllProteins!$H:$H,0) -> 41 | F56: Y | G56: Y | I56: KU749311-volepox_virus | J56: Y
...

Sheet CoreProteinGroups
A1: GroupOrder | B1: GroupName | C1: ProteinFunction
A2: 1 | B2: A18 | C2: DNA helicase
A3: 2 | B3: A22 | C3: holliday junction resolvase
A4: 3 | B4: A23 | C4: VITF-3
A5: 4 | B5: A24 | C5: RPO132
A6: 5 | B6: A28 | C6: IMV-MP
A7: 6 | B7: A2 | C7: VLTF-3
A8: 7 | B8: A32 | C8: ATPase DNA packaging protein
A9: 8 | B9: A3 | C9: P4b
A10: 9 | B10: A7 | C10: VETF-L
A11: 10 | B11: D11 | C11: NPH-I
A12: 11 | B12: D12 | C12: small capping enzyme
A13: 12 | B13: D1 | C13: large capping enzyme
... A26: 25 | B26: L1 | C26: IMV membrane protein

Sheet QC All Proteins Pivot
A3: Count of GeneAccession | B3: Column Labels
A4: Row Labels | B4: A18 | C4: A2 | D4: A22 | E4: A23 | F4: A24 | G4: A28 | H4: A3 | I4: A32 | J4: A7 | K4: D1 | L4: D11 | M4: D12 | N4: D5 | O4: D6 | P4: E1 | Q4: E10 | R4: E9 | S4: G5 | T4: H2 | U4: H4 | V4: H6 | W4: I8 | X4: J3 | Y4: J6 | Z4: L1 | AA4: Grand Total
A5: N | B5: 6 | C5: 6 | D5: 6 | E5: 6 | F5: 6 | G5: 6 | H5: 6 | I5: 6 | J5: 6 | K5: 6 | L5: 6 | M5: 6 | N5: 6 | O5: 6 | P5: 6 | Q5: 6 | R5: 6 | S5: 6 | T5: 6 | U5: 6 | V5: 6 | W5: 6 | X5: 6 | Y5: 6 | Z5: 6 | AA5: 150
A6: BeAn 58058 virus | B6: 1 | C6: 1 | D6: 1 | E6: 1 | F6: 1 | G6: 1 | H6: 1 | I6: 1 | J6: 1 | K6: 1 | L6: 1 | M6: 1 | N6: 1 | O6: 1 | P6: 1 | Q6: 1 | R6: 1 | S6: 1 | T6: 1 | U6: 1 | V6: 1 | W6: 1 | X6: 1 | Y6: 1 | Z6: 1 | AA6: 25
A7: camelpox virus CMS | B7: 1 | C7: 1 | D7: 1 | E7: 1 | F7: 1 | G7: 1 | H7: 1 | I7: 1 | J7: 1 | K7: 1 | L7: 1 | M7: 1 | N7: 1 | O7: 1 | P7: 1 | Q7: 1 | R7: 1 | S7: 1 | T7: 1 | U7: 1 | V7: 1 | W7: 1 | X7: 1 | Y7: 1 | Z7: 1 | AA7: 25
A8: ectromelia virus strain ERPV | B8: 1 | C8: 1 | D8: 1 | E8: 1 | F8: 1 | G8: 1 | H8: 1 | I8: 1 | J8: 1 | K8: 1 | L8: 1 | M8: 1 | N8: 1 | O8: 1 | P8: 1 | Q8: 1 | R8: 1 | S8: 1 | T8: 1 | U8: 1 | V8: 1 | W8: 1 | X8: 1 | Y8: 1 | Z8: 1 | AA8: 25
A9: myxoma virus isolate BRK 897 | B9: 1 | C9: 1 | D9: 1 | E9: 1 | F9: 1 | G9: 1 | H9: 1 | I9: 1 | J9: 1 | K9: 1 | L9: 1 | M9: 1 | N9: 1 | O9: 1 | P9: 1 | Q9: 1 | R9: 1 | S9: 1 | T9: 1 | U9: 1 | V9: 1 | W9: 1 | X9: 1 | Y9: 1 | Z9: 1 | AA9: 25
A10: orf virus strain NZ2 | B10: 1 | C10: 1 | D10: 1 | E10: 1 | F10: 1 | G10: 1 | H10: 1 | I10: 1 | J10: 1 | K10: 1 | L10: 1 | M10: 1 | N10: 1 | O10: 1 | P10: 1 | Q10: 1 | R10: 1 | S10: 1 | T10: 1 | U10: 1 | V10: 1 | W10: 1 | X10: 1 | Y10: 1 | Z10: 1 | AA10: 25
A11: vaccinia virus strain Copenhagen | B11: 1 | C11: 1 | D11: 1 | E11: 1 | F11: 1 | G11: 1 | H11: 1 | I11: 1 | J11: 1 | K11: 1 | L11: 1 | M11: 1 | N11: 1 | O11: 1 | P11: 1 | Q11: 1 | R11: 1 | S11: 1 | T11: 1 | U11: 1 | V11: 1 | W11: 1 | X11: 1 | Y11: 1 | Z11: 1 | AA11: 25
A12: Y | B12: 56 | C12: 56 | D12: 56 | E12: 56 | F12: 56 | G12: 56 | H12: 56 | I12: 56 | J12: 56 | K12: 56 | L12: 56 | M12: 56 | N12: 56 | O12: 56 | P12: 56 | Q12: 56 | R12: 56 | S12: 56 | T12: 56 | U12: 56 | V12: 56 | W12: 56 | X12: 56 | Y12: 56 | Z12: 56 | AA12: 1400
A13: Adoxophyes honmai entomopoxvirus | B13: 1 | C13: 1 | D13: 1 | E13: 1 | F13: 1 | G13: 1 | H13: 1 | I13: 1 | J13: 1 | K13: 1 | L13: 1 | M13: 1 | N13: 1 | O13: 1 | P13: 1 | Q13: 1 | R13: 1 | S13: 1 | T13: 1 | U13: 1 | V13: 1 | W13: 1 | X13: 1 | Y13: 1 | Z13: 1 | AA13: 25
A14: Akhmeta virus | B14: 1 | C14: 1 | D14: 1 | E14: 1 | F14: 1 | G14: 1 | H14: 1 | I14: 1 | J14: 1 | K14: 1 | L14: 1 | M14: 1 | N14: 1 | O14: 1 | P14: 1 | Q14: 1 | R14: 1 | S14: 1 | T14: 1 | U14: 1 | V14: 1 | W14: 1 | X14: 1 | Y14: 1 | Z14: 1 | AA14: 25
A15: Amsacta moorei entomopoxvirus | B15: 1 | C15: 1 | D15: 1 | E15: 1 | F15: 1 | G15: 1 | H15: 1 | I15: 1 | J15: 1 | K15: 1 | L15: 1 | M15: 1 | N15: 1 | O15: 1 | P15: 1 | Q15: 1 | R15: 1 | S15: 1 | T15: 1 | U15: 1 | V15: 1 | W15: 1 | X15: 1 | Y15: 1 | Z15: 1 | AA15: 25
A16: Anomala cuprea entomopoxvirus | B16: 1 | C16: 1 | D16: 1 | E16: 1 | F16: 1 | G16: 1 | H16: 1 | I16: 1 | J16: 1 | K16: 1 | L16: 1 | M16: 1 | N16: 1 | O16: 1 | P16: 1 | Q16: 1 | R16: 1 | S16: 1 | T16: 1 | U16: 1 | V16: 1 | W16: 1 | X16: 1 | Y16: 1 | Z16: 1 | AA16: 25
... A69: Grand Total | B69: 62 | C69: 62 | D69: 62 | E69: 62 | F69: 62 | G69: 62 | H69: 62 | I69: 62 | J69: 62 | K69: 62 | L69: 62 | M69: 62 | N69: 62 | O69: 62 | P69: 62 | Q69: 62 | R69: 62 | S69: 62 | T69: 62 | U69: 62 | V69: 62 | W69: 62 | X69: 62 | Y69: 62 | Z69: 62 | AA69: 1550
